Workbook

Sheet Resumen
B2: Clasificación de mariposas colombianas — Papilionidae vs. Pieridae
B3: Análisis cuantitativo y cualitativo de las etapas de segmentación, color y textura
B5: Autores
B6: Juan Daniel Moreno Bonilla — Código 1202513
B7: Juan Camilo Niño Rodrigues — Código 1202498
B8: Universidad Militar Nueva Granada — Ingeniería Multimedia — Reconocimiento de Patrones
B9: Corte 2 — Avance de proyecto: preprocesamiento y caracterización
B11: Alcance del dataset
B12: Familias incluidas (fauna colombiana):
B13: Papilionidae | C13: =COUNTIF(Datos_Color!$B:$B,"Papilionidae") -> 285
B14: Pieridae | C14: =COUNTIF(Datos_Color!$B:$B,"Pieridae") -> 527
B15: Total de imágenes caracterizadas | C15: =SUM(C13:C14) -> 812
B17: Pipeline de procesamiento
B18: 1. Segmentación (Segmentacion.py)
B19: GrabCut inicializado con rectángulo + limpieza morfológica (apertura/cierre), se conserva el componente conexo más grande y se rellenan huecos internos. Fallback a Otsu si GrabCut falla. Salida: máscara binaria + recorte sobre fondo blanco.
B21: 2. Color (color_features.py)
B22: Histogramas HSV (16 bins/canal) + momentos estadísticos (media, desviación estándar, asimetría) en BGR y HSV, calculados únicamente sobre los píxeles de primer plano (máscara).
B24: 3. Textura (texturas.py)
B25: GLCM (scikit-image: contraste, disimilitud, homogeneidad, energía, correlación, ASM a distancias 1-2-3 px y 4 ángulos) + Haralick (mahotas, 13 descriptores) + banco de filtros de Gabor (4 frecuencias x 4 orientaciones), todos excluyendo el fondo.
B28: Ver hojas: Datos_Color, Datos_Textura, Descriptivos, Separabilidad, Clasificacion_Baseline, PCA, Conclusiones

Sheet Descriptivos
B2: Estadísticos descriptivos por familia — características más relevantes
B3: Media y desviación estándar calculadas con fórmulas (AVERAGEIF / SUMPRODUCT) sobre las hojas Datos_Color y Datos_Textura.
B5: Característica | C5: Grupo | D5: Media Papilionidae | E5: Desv. Est. Papilionidae | F5: Media Pieridae | G5: Desv. Est. Pieridae | H5: |Cohen's d|
B6: moment_bgr_g_mean | C6: color | D6: =AVERAGEIF(Datos_Color!$B$2:$B$813,"Papilionidae",Datos_Color!$BD$2:$BD$813) -> 73.410857 | E6: =SQRT(SUMPRODUCT((Datos_Color!$B$2:$B$813="Papilionidae")*(Datos_Color!$BD$2:$BD$813-D6)^2)/(COUNTIF(Datos_Color!$B$2:$B$813,"Papilionidae")-1)) -> 32.002392 | F6: =AVERAGEIF(Datos_Color!$B$2:$B$813,"Pieridae",Datos_Color!$BD$2:$BD$813) -> 135.8567 | G6: =SQRT(SUMPRODUCT((Datos_Color!$B$2:$B$813="Pieridae")*(Datos_Color!$BD$2:$BD$813-F6)^2)/(COUNTIF(Datos_Color!$B$2:$B$813,"Pieridae")-1)) -> 41.091009 | H6: 1.636779
B7: haralick_sum_average | C7: textura | D7: =AVERAGEIF(Datos_Textura!$B$2:$B$813,"Papilionidae",Datos_Textura!$CD$2:$CD$813) -> 148.6559 | E7: =SQRT(SUMPRODUCT((Datos_Textura!$B$2:$B$813="Papilionidae")*(Datos_Textura!$CD$2:$CD$813-D7)^2)/(COUNTIF(Datos_Textura!$B$2:$B$813,"Papilionidae")-1)) -> 62.526526 | F7: =AVERAGEIF(Datos_Textura!$B$2:$B$813,"Pieridae",Datos_Textura!$CD$2:$CD$813) -> 265.9873 | G7: =SQRT(SUMPRODUCT((Datos_Textura!$B$2:$B$813="Pieridae")*(Datos_Textura!$CD$2:$CD$813-F7)^2)/(COUNTIF(Datos_Textura!$B$2:$B$813,"Pieridae")-1)) -> 77.136676 | H7: 1.6217025
B8: moment_hsv_v_mean | C8: color | D8: =AVERAGEIF(Datos_Color!$B$2:$B$813,"Papilionidae",Datos_Color!$BP$2:$BP$813) -> 85.775381 | E8: =SQRT(SUMPRODUCT((Datos_Color!$B$2:$B$813="Papilionidae")*(Datos_Color!$BP$2:$BP$813-D8)^2)/(COUNTIF(Datos_Color!$B$2:$B$813,"Papilionidae")-1)) -> 32.977037 | F8: =AVERAGEIF(Datos_Color!$B$2:$B$813,"Pieridae",Datos_Color!$BP$2:$BP$813) -> 146.30742 | G8: =SQRT(SUMPRODUCT((Datos_Color!$B$2:$B$813="Pieridae")*(Datos_Color!$BP$2:$BP$813-F8)^2)/(COUNTIF(Datos_Color!$B$2:$B$813,"Pieridae")-1)) -> 40.27913 | H8: 1.5980168
B9: moment_bgr_r_mean | C9: color | D9: =AVERAGEIF(Datos_Color!$B$2:$B$813,"Papilionidae",Datos_Color!$BG$2:$BG$813) -> 82.739192 | E9: =SQRT(SUMPRODUCT((Datos_Color!$B$2:$B$813="Papilionidae")*(Datos_Color!$BG$2:$BG$813-D9)^2)/(COUNTIF(Datos_Color!$B$2:$B$813,"Papilionidae")-1)) -> 32.795888 | F9: =AVERAGEIF(Datos_Color!$B$2:$B$813,"Pieridae",Datos_Color!$BG$2:$BG$813) -> 141.00322 | G9: =SQRT(SUMPRODUCT((Datos_Color!$B$2:$B$813="Pieridae")*(Datos_Color!$BG$2:$BG$813-F9)^2)/(COUNTIF(Datos_Color!$B$2:$B$813,"Pieridae")-1)) -> 39.966017 | H9: 1.5492459
B10: moment_bgr_r_skew | C10: color | D10: =AVERAGEIF(Datos_Color!$B$2:$B$813,"Papilionidae",Datos_Color!$BH$2:$BH$813) -> 1.2613393 | E10: =SQRT(SUMPRODUCT((Datos_Color!$B$2:$B$813="Papilionidae")*(Datos_Color!$BH$2:$BH$813-D10)^2)/(COUNTIF(Datos_Color!$B$2:$B$813,"Papilionidae")-1)) -> 1.0174812 | F10: =AVERAGEIF(Datos_Color!$B$2:$B$813,"Pieridae",Datos_Color!$BH$2:$BH$813) -> -0.34929475 | G10: =SQRT(SUMPRODUCT((Datos_Color!$B$2:$B$813="Pieridae")*(Datos_Color!$BH$2:$BH$813-F10)^2)/(COUNTIF(Datos_Color!$B$2:$B$813,"Pieridae")-1)) -> 1.1429633 | H10: 1.4634185
B11: moment_hsv_v_skew | C11: color | D11: =AVERAGEIF(Datos_Color!$B$2:$B$813,"Papilionidae",Datos_Color!$BQ$2:$BQ$813) -> 1.2236457 | E11: =SQRT(SUMPRODUCT((Datos_Color!$B$2:$B$813="Papilionidae")*(Datos_Color!$BQ$2:$BQ$813-D11)^2)/(COUNTIF(Datos_Color!$B$2:$B$813,"Papilionidae")-1)) -> 1.0069052 | F11: =AVERAGEIF(Datos_Color!$B$2:$B$813,"Pieridae",Datos_Color!$BQ$2:$BQ$813) -> -0.4112601 | G11: =SQRT(SUMPRODUCT((Datos_Color!$B$2:$B$813="Pieridae")*(Datos_Color!$BQ$2:$BQ$813-F11)^2)/(COUNTIF(Datos_Color!$B$2:$B$813,"Pieridae")-1)) -> 1.1828307 | H11: 1.454172
B12: moment_bgr_g_skew | C12: color | D12: =AVERAGEIF(Datos_Color!$B$2:$B$813,"Papilionidae",Datos_Color!$BE$2:$BE$813) -> 1.3215204 | E12: =SQRT(SUMPRODUCT((Datos_Color!$B$2:$B$813="Papilionidae")*(Datos_Color!$BE$2:$BE$813-D12)^2)/(COUNTIF(Datos_Color!$B$2:$B$813,"Papilionidae")-1)) -> 1.0622625 | F12: =AVERAGEIF(Datos_Color!$B$2:$B$813,"Pieridae",Datos_Color!$BE$2:$BE$813) -> -0.32090858 | G12: =SQRT(SUMPRODUCT((Datos_Color!$B$2:$B$813="Pieridae")*(Datos_Color!$BE$2:$BE$813-F12)^2)/(COUNTIF(Datos_Color!$B$2:$B$813,"Pieridae")-1)) -> 1.1933296 | H12: 1.4293445
B13: hist_v_02 | C13: color | D13: =AVERAGEIF(Datos_Color!$B$2:$B$813,"Papilionidae",Datos_Color!$AM$2:$AM$813) -> 0.0095428442 | E13: =SQRT(SUMPRODUCT((Datos_Color!$B$2:$B$813="Papilionidae")*(Datos_Color!$AM$2:$AM$813-D13)^2)/(COUNTIF(Datos_Color!$B$2:$B$813,"Papilionidae")-1)) -> 0.0061155609 | F13: =AVERAGEIF(Datos_Color!$B$2:$B$813,"Pieridae",Datos_Color!$AM$2:$AM$813) -> 0.0029937525 | G13: =SQRT(SUMPRODUCT((Datos_Color!$B$2:$B$813="Pieridae")*(Datos_Color!$AM$2:$AM$813-F13)^2)/(COUNTIF(Datos_Color!$B$2:$B$813,"Pieridae")-1)) -> 0.0046194503 | H13: 1.2610623
B14: hist_v_01 | C14: color | D14: =AVERAGEIF(Datos_Color!$B$2:$B$813,"Papilionidae",Datos_Color!$AL$2:$AL$813) -> 0.010085449 | E14: =SQRT(SUMPRODUCT((Datos_Color!$B$2:$B$813="Papilionidae")*(Datos_Color!$AL$2:$AL$813-D14)^2)/(COUNTIF(Datos_Color!$B$2:$B$813,"Papilionidae")-1)) -> 0.0083376915 | F14: =AVERAGEIF(Datos_Color!$B$2:$B$813,"Pieridae",Datos_Color!$AL$2:$AL$813) -> 0.0024445534 | G14: =SQRT(SUMPRODUCT((Datos_Color!$B$2:$B$813="Pieridae")*(Datos_Color!$AL$2:$AL$813-F14)^2)/(COUNTIF(Datos_Color!$B$2:$B$813,"Pieridae")-1)) -> 0.0052479893 | H14: 1.1753999
B15: moment_bgr_b_skew | C15: color | D15: =AVERAGEIF(Datos_Color!$B$2:$B$813,"Papilionidae",Datos_Color!$BB$2:$BB$813) -> 1.5239449 | E15: =SQRT(SUMPRODUCT((Datos_Color!$B$2:$B$813="Papilionidae")*(Datos_Color!$BB$2:$BB$813-D15)^2)/(COUNTIF(Datos_Color!$B$2:$B$813,"Papilionidae")-1)) -> 0.9897456 | F15: =AVERAGEIF(Datos_Color!$B$2:$B$813,"Pieridae",Datos_Color!$BB$2:$BB$813) -> 0.24049562 | G15: =SQRT(SUMPRODUCT((Datos_Color!$B$2:$B$813="Pieridae")*(Datos_Color!$BB$2:$BB$813-F15)^2)/(COUNTIF(Datos_Color!$B$2:$B$813,"Pieridae")-1)) -> 1.1721835 | H15: 1.1545637
B16: moment_bgr_b_mean | C16: color | D16: =AVERAGEIF(Datos_Color!$B$2:$B$813,"Papilionidae",Datos_Color!$BA$2:$BA$813) -> 57.031512 | E16: =SQRT(SUMPRODUCT((Datos_Color!$B$2:$B$813="Papilionidae")*(Datos_Color!$BA$2:$BA$813-D16)^2)/(COUNTIF(Datos_Color!$B$2:$B$813,"Papilionidae")-1)) -> 28.258473 | F16: =AVERAGEIF(Datos_Color!$B$2:$B$813,"Pieridae",Datos_Color!$BA$2:$BA$813) -> 95.587669 | G16: =SQRT(SUMPRODUCT((Datos_Color!$B$2:$B$813="Pieridae")*(Datos_Color!$BA$2:$BA$813-F16)^2)/(COUNTIF(Datos_Color!$B$2:$B$813,"Pieridae")-1)) -> 42.183589 | H16: 1.0176247
B17: hist_v_03 | C17: color | D17: =AVERAGEIF(Datos_Color!$B$2:$B$813,"Papilionidae",Datos_Color!$AN$2:$AN$813) -> 0.0075151985 | E17: =SQRT(SUMPRODUCT((Datos_Color!$B$2:$B$813="Papilionidae")*(Datos_Color!$AN$2:$AN$813-D17)^2)/(COUNTIF(Datos_Color!$B$2:$B$813,"Papilionidae")-1)) -> 0.0046262685 | F17: =AVERAGEIF(Datos_Color!$B$2:$B$813,"Pieridae",Datos_Color!$AN$2:$AN$813) -> 0.0031474929 | G17: =SQRT(SUMPRODUCT((Datos_Color!$B$2:$B$813="Pieridae")*(Datos_Color!$AN$2:$AN$813-F17)^2)/(COUNTIF(Datos_Color!$B$2:$B$813,"Pieridae")-1)) -> 0.004307363 | H17: 0.98776735
B18: moment_hsv_h_std | C18: color | D18: =AVERAGEIF(Datos_Color!$B$2:$B$813,"Papilionidae",Datos_Color!$BL$2:$BL$813) -> 34.833999 | E18: =SQRT(SUMPRODUCT((Datos_Color!$B$2:$B$813="Papilionidae")*(Datos_Color!$BL$2:$BL$813-D18)^2)/(COUNTIF(Datos_Color!$B$2:$B$813,"Papilionidae")-1)) -> 17.738535 | F18: =AVERAGEIF(Datos_Color!$B$2:$B$813,"Pieridae",Datos_Color!$BL$2:$BL$813) -> 19.255726 | G18: =SQRT(SUMPRODUCT((Datos_Color!$B$2:$B$813="Pieridae")*(Datos_Color!$BL$2:$BL$813-F18)^2)/(COUNTIF(Datos_Color!$B$2:$B$813,"Pieridae")-1)) -> 15.277168 | H18: 0.96264145
B19: gabor_f0.1_t45_std | C19: textura | D19: =AVERAGEIF(Datos_Textura!$B$2:$B$813,"Papilionidae",Datos_Textura!$J$2:$J$813) -> 0.0099419298 | E19: =SQRT(SUMPRODUCT((Datos_Textura!$B$2:$B$813="Papilionidae")*(Datos_Textura!$J$2:$J$813-D19)^2)/(COUNTIF(Datos_Textura!$B$2:$B$813,"Papilionidae")-1)) -> 0.0037856877 | F19: =AVERAGEIF(Datos_Textura!$B$2:$B$813,"Pieridae",Datos_Textura!$J$2:$J$813) -> 0.0068545202 | G19: =SQRT(SUMPRODUCT((Datos_Textura!$B$2:$B$813="Pieridae")*(Datos_Textura!$J$2:$J$813-F19)^2)/(COUNTIF(Datos_Textura!$B$2:$B$813,"Pieridae")-1)) -> 0.0032810124 | H19: 0.89068407
B20: hist_v_10 | C20: color | D20: =AVERAGEIF(Datos_Color!$B$2:$B$813,"Papilionidae",Datos_Color!$AU$2:$AU$813) -> 0.0017744864 | E20: =SQRT(SUMPRODUCT((Datos_Color!$B$2:$B$813="Papilionidae")*(Datos_Color!$AU$2:$AU$813-D20)^2)/(COUNTIF(Datos_Color!$B$2:$B$813,"Papilionidae")-1)) -> 0.0020066751 | F20: =AVERAGEIF(Datos_Color!$B$2:$B$813,"Pieridae",Datos_Color!$AU$2:$AU$813) -> 0.0063527762 | G20: =SQRT(SUMPRODUCT((Datos_Color!$B$2:$B$813="Pieridae")*(Datos_Color!$AU$2:$AU$813-F20)^2)/(COUNTIF(Datos_Color!$B$2:$B$813,"Pieridae")-1)) -> 0.0062932891 | H20: 0.87896311
B21: hist_v_11 | C21: color | D21: =AVERAGEIF(Datos_Color!$B$2:$B$813,"Papilionidae",Datos_Color!$AV$2:$AV$813) -> 0.0016718961 | E21: =SQRT(SUMPRODUCT((Datos_Color!$B$2:$B$813="Papilionidae")*(Datos_Color!$AV$2:$AV$813-D21)^2)/(COUNTIF(Datos_Color!$B$2:$B$813,"Papilionidae")-1)) -> 0.0020202772 | F21: =AVERAGEIF(Datos_Color!$B$2:$B$813,"Pieridae",Datos_Color!$AV$2:$AV$813) -> 0.0068678832 | G21: =SQRT(SUMPRODUCT((Datos_Color!$B$2:$B$813="Pieridae")*(Datos_Color!$AV$2:$AV$813-F21)^2)/(COUNTIF(Datos_Color!$B$2:$B$813,"Pieridae")-1)) -> 0.0072044431 | H21: 0.87657307
B22: gabor_f0.1_t0_std | C22: textura | D22: =AVERAGEIF(Datos_Textura!$B$2:$B$813,"Papilionidae",Datos_Textura!$F$2:$F$813) -> 0.0097317409 | E22: =SQRT(SUMPRODUCT((Datos_Textura!$B$2:$B$813="Papilionidae")*(Datos_Textura!$F$2:$F$813-D22)^2)/(COUNTIF(Datos_Textura!$B$2:$B$813,"Papilionidae")-1)) -> 0.0036331567 | F22: =AVERAGEIF(Datos_Textura!$B$2:$B$813,"Pieridae",Datos_Textura!$F$2:$F$813) -> 0.0069485449 | G22: =SQRT(SUMPRODUCT((Datos_Textura!$B$2:$B$813="Pieridae")*(Datos_Textura!$F$2:$F$813-F22)^2)/(COUNTIF(Datos_Textura!$B$2:$B$813,"Pieridae")-1)) -> 0.003161599 | H22: 0.83465775
B23: gabor_f0.2_t0_std | C23: textura | D23: =AVERAGEIF(Datos_Textura!$B$2:$B$813,"Papilionidae",Datos_Textura!$N$2:$N$813) -> 0.0076410037 | E23: =SQRT(SUMPRODUCT((Datos_Textura!$B$2:$B$813="Papilionidae")*(Datos_Textura!$N$2:$N$813-D23)^2)/(COUNTIF(Datos_Textura!$B$2:$B$813,"Papilionidae")-1)) -> 0.0026696905 | F23: =AVERAGEIF(Datos_Textura!$B$2:$B$813,"Pieridae",Datos_Textura!$N$2:$N$813) -> 0.00571485 | G23: =SQRT(SUMPRODUCT((Datos_Textura!$B$2:$B$813="Pieridae")*(Datos_Textura!$N$2:$N$813-F23)^2)/(COUNTIF(Datos_Textura!$B$2:$B$813,"Pieridae")-1)) -> 0.0021874227 | H23: 0.81350451
B24: hist_v_00 | C24: color | D24: =AVERAGEIF(Datos_Color!$B$2:$B$813,"Papilionidae",Datos_Color!$AK$2:$AK$813) -> 0.0043655193 | E24: =SQRT(SUMPRODUCT((Datos_Color!$B$2:$B$813="Papilionidae")*(Datos_Color!$AK$2:$AK$813-D24)^2)/(COUNTIF(Datos_Color!$B$2:$B$813,"Papilionidae")-1)) -> 0.0067264491 | F24: =AVERAGEIF(Datos_Color!$B$2:$B$813,"Pieridae",Datos_Color!$AK$2:$AK$813) -> 0.00065125074 | G24: =SQRT(SUMPRODUCT((Datos_Color!$B$2:$B$813="Pieridae")*(Datos_Color!$AK$2:$AK$813-F24)^2)/(COUNTIF(Datos_Color!$B$2:$B$813,"Pieridae")-1)) -> 0.0028027704 | H24: 0.8111969
B25: gabor_f0.2_t45_std | C25: textura | D25: =AVERAGEIF(Datos_Textura!$B$2:$B$813,"Papilionidae",Datos_Textura!$R$2:$R$813) -> 0.0073833927 | E25: =SQRT(SUMPRODUCT((Datos_Textura!$B$2:$B$813="Papilionidae")*(Datos_Textura!$R$2:$R$813-D25)^2)/(COUNTIF(Datos_Textura!$B$2:$B$813,"Papilionidae")-1)) -> 0.0025852725 | F25: =AVERAGEIF(Datos_Textura!$B$2:$B$813,"Pieridae",Datos_Textura!$R$2:$R$813) -> 0.0054668244 | G25: =SQRT(SUMPRODUCT((Datos_Textura!$B$2:$B$813="Pieridae")*(Datos_Textura!$R$2:$R$813-F25)^2)/(COUNTIF(Datos_Textura!$B$2:$B$813,"Pieridae")-1)) -> 0.002271686 | H25: 0.80314445
B27: Nota: |Cohen's d| indica el tamaño del efecto entre familias (>0.8 = grande). Calculado en Python (pandas/numpy) sobre las mismas columnas; ver hoja Separabilidad.

Sheet Separabilidad
B2: Separabilidad entre familias — tamaño del efecto (Cohen's d) e importancia en el modelo
B3: Cohen's d calculado con SciPy/NumPy sobre las hojas Datos_Color y Datos_Textura; importancia de variable según Random Forest (scikit-image/scikit-learn).
B5: Característica | C5: Grupo | D5: Cohen's d (signo) | E5: |d|
B6: moment_bgr_g_mean | C6: color | D6: -1.637 | E6: 1.637
B7: haralick_sum_average | C7: textura | D7: -1.622 | E7: 1.622
B8: moment_hsv_v_mean | C8: color | D8: -1.598 | E8: 1.598
B9: moment_bgr_r_mean | C9: color | D9: -1.549 | E9: 1.549
B10: moment_bgr_r_skew | C10: color | D10: 1.463 | E10: 1.463
B11: moment_hsv_v_skew | C11: color | D11: 1.454 | E11: 1.454
B12: moment_bgr_g_skew | C12: color | D12: 1.429 | E12: 1.429
B13: hist_v_02 | C13: color | D13: 1.261 | E13: 1.261
B14: hist_v_01 | C14: color | D14: 1.175 | E14: 1.175
B15: moment_bgr_b_skew | C15: color | D15: 1.155 | E15: 1.155
B16: moment_bgr_b_mean | C16: color | D16: -1.018 | E16: 1.018
B17: hist_v_03 | C17: color | D17: 0.988 | E17: 0.988
... B25: gabor_f0.2_t45_std | C25: textura | D25: 0.803 | E25: 0.803
B27: Lectura: valores positivos = mayor en Pieridae; negativos = mayor en Papilionidae (ver medias en hoja Descriptivos). |d|>0.8 se considera un efecto grande (Cohen, 1988).

Sheet Graficos
B2: Ayudas visuales — comportamiento de media, desviación estándar y Cohen's d
B3: Violin plots construidos con los datos reales de Datos_Color / Datos_Textura (no simulados a partir de la tabla de resumen).

Sheet Clasificacion_Baseline
B2: Prueba base de clasificación (Random Forest, validación cruzada 5-fold)
B3: Objetivo: cuantificar cuánta información discriminante aporta cada grupo de características entre Papilionidae y Pieridae, antes de definir el clasificador final del proyecto.
B5: Conjunto de características | C5: Exactitud media (5-fold) | D5: Desv. estándar
B6: Solo color | C6: 0.8485 | D6: 0.0243
B7: Solo textura | C7: 0.8461 | D7: 0.0138
B8: Color + Textura | C8: 0.8707 | D8: 0.0139
B9: Línea base (clase mayoritaria = Pieridae) | C9: 0.649
B11: Top variables por importancia (Random Forest, conjunto combinado):
B12: Característica | C12: Importancia
B13: moment_bgr_g_mean | C13: 0.0488
B14: hist_v_01 | C14: 0.047
B15: haralick_sum_average | C15: 0.0459
B16: moment_hsv_v_mean | C16: 0.0329
B17: moment_bgr_r_mean | C17: 0.0313
B18: hist_v_00 | C18: 0.0304
B19: moment_hsv_v_skew | C19: 0.0297
B20: hist_v_02 | C20: 0.0249
B21: hist_v_10 | C21: 0.0232
B22: moment_bgr_r_skew | C22: 0.0227
B24: Metodología: RandomForestClassifier (300 árboles, scikit-learn) con estandarización previa (StandardScaler), validación cruzada estratificada de 5 particiones. Calculado en Python; valores documentados aquí como resultado del experimento (no recalculables por fórmula de hoja de cálculo).

Sheet PCA
B2: Análisis de Componentes Principales (visualización de separabilidad)
B3: PCA calculado con scikit-learn sobre variables estandarizadas. Color: PC1=21.0%, PC2=14.8% de varianza explicada. Textura: PC1=55.2%, PC2=13.5%.
B5: filename | C5: familia | D5: pc1_color | E5: pc2_color | F5: pc1_textura | G5: pc2_textura
B6: 001_Battus_crassus_crassus.png | C6: Papilionidae | D6: -4.5488 | E6: -0.6789 | F6: -2.2391 | G6: -1.6849
B7: 182_Parides_eurimedes_arriphus.png | C7: Papilionidae | D7: -0.9787 | E7: 1.7017 | F7: 5.5116 | G7: -0.2071
B8: 183_Parides_eurimedes_mycale.png | C8: Papilionidae | D8: -4.8514 | E8: 1.6882 | F8: -7.5758 | G8: -1.7338
B9: 184_Parides_eurimedes_mycale.png | C9: Papilionidae | D9: -0.6249 | E9: -1.7886 | F9: 0.3191 | G9: -0.35
B10: 185_Parides_eurimedes_mycale.png | C10: Papilionidae | D10: -5.5101 | E10: 2.0062 | F10: -9.8888 | G10: -3.3659
B11: 186_Parides_eurimedes_mycale.png | C11: Papilionidae | D11: -5.0004 | E11: -1.7763 | F11: 5.1255 | G11: -2.0095
B12: 187_Parides_eurimedes_timias.png | C12: Papilionidae | D12: -4.5937 | E12: -0.5777 | F12: -7.3332 | G12: -2.2699
B13: 188_Parides_eurimedes_timias.png | C13: Papilionidae | D13: -0.4443 | E13: 1.6625 | F13: 13.7236 | G13: -1.6523
B14: 189_Parides_eurimedes_timias.png | C14: Papilionidae | D14: -5.8763 | E14: -1.8558 | F14: -4.7547 | G14: -1.5065
B15: 190_Parides_eurimedes_timias.png | C15: Papilionidae | D15: -5.2396 | E15: -0.1787 | F15: -5.2127 | G15: -0.1161
B16: 191_Parides_iphidamas.png | C16: Papilionidae | D16: -5.6017 | E16: -1.83 | F16: 2.0302 | G16: -1.9757
B17: 192_Parides_iphidamas_phalias.png | C17: Papilionidae | D17: -4.1534 | E17: 2.0417 | F17: -7.0283 | G17: -2.1785
... B817: 534_Tatochila_xanthodice_xanthodice.png | C817: Pieridae | D817: 1.334 | E817: -2.1072 | F817: 4.5334 | G817: 7.6724

Sheet Conclusiones
B2: Análisis cualitativo — lectura de resultados
B4: Segmentación
B5: • GrabCut con inicialización rectangular aísla bien la silueta cuando el fondo tiene contraste con la mariposa (ver muestra: Battus laodamas laodamas), incluyendo casos con alas separadas del cuerpo por el flash, gracias al relleno de huecos internos.
B6: • El caso 052_Dismorphia_lua_id_ae muestra una máscara reducida a un solo triángulo (una sola ala), lo que sugiere que en imágenes con fondo poco contrastado o mariposa parcialmente fuera de encuadre, GrabCut puede converger a una región incompleta; conviene revisar visualmente el lote de 'preview/' antes de dar por buena la etapa.
B7: • El promedio de píxeles de primer plano (fg_pixels) es de aproximadamente 92 000 px con alta dispersión (std ≈ 56 000), lo cual es esperable: cada especie e imagen tiene tamaño y encuadre distintos, pero conviene verificar los extremos (mínimo ≈ 6 300 px) para descartar segmentaciones fallidas.
B9: Color
B10: • El color es, hasta ahora, el grupo de características más separador entre familias: 9 de las 10 variables con mayor Cohen's d son de color (momentos de brillo/valor y canal verde-rojo, e histogramas de V).
B11: • Papilionidae presenta tonos más oscuros y saturados (menor V medio, mayor asimetría positiva hacia tonos oscuros), consistente con las alas negras/marrones con manchas de color de muchas especies del género Battus/Parides/Heraclides.
B12: • Pieridae presenta valores de brillo (V) sistemáticamente más altos, coherente con la coloración blanca/amarilla típica de la familia (Catasticta, Leptophobia, Eurema, Phoebis).
B14: Textura
B15: • Dentro de textura, el descriptor Haralick 'sum_average' y varias estadísticas de Gabor a baja frecuencia (0.1–0.2 ciclos/px, orientaciones 0° y 45°) son las más discriminantes; esto sugiere que el patrón de veteado de las alas difiere en granularidad/orientación entre familias, más que en su nivel de contraste puro (GLCM 'contrast' no aparece entre las 20 variables más separadoras).
B16: • El baseline de clasificación (Random Forest, 5-fold) obtiene una exactitud similar usando solo color (≈84.9%) o solo textura (≈84.6%), y mejora al combinarlos (≈87.1%), frente a una línea base de 64.9% (predecir siempre la clase mayoritaria). Esto confirma que ambos grupos de características aportan información complementaria y respalda avanzar con un clasificador que use ambos conjuntos.
... B21: • Se recomienda revisar manualmente el lote de máscaras con fg_pixels por debajo del percentil 5 para confirmar que no son segmentaciones fallidas antes de usarlas para entrenar el modelo final.

Sheet Datos_Color
A1: filename | B1: familia | C1: genero | D1: fg_pixels | E1: hist_h_00 | F1: hist_h_01 | G1: hist_h_02 | H1: hist_h_03 | I1: hist_h_04 | J1: hist_h_05 | K1: hist_h_06 | L1: hist_h_07 | M1: hist_h_08 | N1: hist_h_09 | O1: hist_h_10 | P1: hist_h_11 | Q1: hist_h_12 | R1: hist_h_13 | S1: hist_h_14 | T1: hist_h_15 | U1: hist_s_00 | V1: hist_s_01 | W1: hist_s_02 | X1: hist_s_03 | Y1: hist_s_04 | Z1: hist_s_05 | AA1: hist_s_06 | AB1: hist_s_07 | AC1: hist_s_08 | AD1: hist_s_09 | AE1: hist_s_10 | AF1: hist_s_11 | AG1: hist_s_12 | AH1: hist_s_13 | AI1: hist_s_14 | AJ1: hist_s_15 | AK1: hist_v_00 | AL1: hist_v_01 | AM1: hist_v_02 | AN1: hist_v_03 | AO1: hist_v_04 | AP1: hist_v_05 | AQ1: hist_v_06 | AR1: hist_v_07 | AS1: hist_v_08 | AT1: hist_v_09 | AU1: hist_v_10 | AV1: hist_v_11 | AW1: hist_v_12 | AX1: hist_v_13 | AY1: hist_v_14 | AZ1: hist_v_15 | BA1: moment_bgr_b_mean | BB1: moment_bgr_b_skew | BC1: moment_bgr_b_std | BD1: moment_bgr_g_mean | BE1: moment_bgr_g_skew | BF1: moment_bgr_g_std | BG1: moment_bgr_r_mean | BH1: moment_bgr_r_skew | BI1: moment_bgr_r_std | BJ1: moment_hsv_h_mean | BK1: moment_hsv_h_skew | BL1: moment_hsv_h_std | BM1: moment_hsv_s_mean | BN1: moment_hsv_s_skew | BO1: moment_hsv_s_std | BP1: moment_hsv_v_mean | BQ1: moment_hsv_v_skew | BR1: moment_hsv_v_std
A2: 001_Battus_crassus_crassus.png | B2: Papilionidae | C2: Battus | D2: 82002 | E2: 0.0063825002 | F2: 0.01184795 | G2: 0.0033820313 | H2: 0.014096133 | I2: 0.0092789065 | J2: 0.0044963673 | K2: 0.0030470802 | L2: 0.0094935354 | M2: 0.009797051 | N2: 0.014161172 | O2: 0.00093439455 | P2: 0.00056150392 | Q2: 0.00031218751 | R2: 0.00018427735 | S2: 0.00037722657 | T2: 0.00053657228 | U2: 0.0039076791 | V2: 0.0046881479 | W2: 0.0050943879 | X2: 0.0046934831 | Y2: 0.0062765237 | Z2: 0.0075989 | AA2: 0.009243677 | AB2: 0.0055539804 | AC2: 0.005422886 | AD2: 0.0034206483 | AE2: 0.0021089425 | AF2: 0.0012873162 | AG2: 0.00070882418 | AH2: 0.00048474427 | AI2: 0.00030563279 | AJ2: 0.0017042267 | AK2: 0.011955501 | AL2: 0.032942032 | AM2: 0.0083755579 | AN2: 0.0018368454 | AO2: 0.00057544328 | AP2: 0.00046645204 | AQ2: 0.00046568986 | AR2: 0.0006105034 | AS2: 0.00074998171 | AT2: 0.0008185776 | AU2: 0.00067528841 | AV2: 0.00060135728 | AW2: 0.0008444916 | AX2: 0.0011760384 | AY2: 0.00034602815 | AZ2: 6.0211946e-05 | BA2: 33.65535 | BB2: 2.643826 | BC2: 43.460956 | BD2: 37.135948 | BE2: 2.7160994 | BF2: 48.002222 | BG2: 32.428331 | BH2: 2.7132196 | BI2: 44.722606 | BJ2: 61.173776 | BK2: 0.20791523 | BL2: 37.013736 | BM2: 94.329297 | BN2: 0.58102827 | BO2: 55.710353 | BP2: 39.616839 | BQ2: 2.6721857 | BR2: 47.442506
A3: 002_Battus_crassus_crassus.png | B3: Papilionidae | C3: Battus | D3: 74842 | E3: 0.013172639 | F3: 0.041690198 | G3: 0.013792612 | H3: 0.0041592807 | I3: 0.00065916642 | J3: 0.00018290384 | K3: 0.00023516207 | L3: 0.00036105692 | M3: 0.00030048487 | N3: 0.00080881501 | O3: 0.0011841242 | P3: 0.0021402124 | Q3: 0.0019193026 | R3: 0.0017779678 | S3: 0.0017221465 | T3: 0.0047828165 | U3: 0.011592755 | V3: 0.011705493 | W3: 0.0085997835 | X3: 0.0082448692 | Y3: 0.0072227159 | Z3: 0.0054306071 | AA3: 0.0034380762 | AB3: 0.0017829227 | AC3: 0.0010355148 | AD3: 0.00060293685 | AE3: 0.00048435371 | AF3: 0.00044510435 | AG3: 0.00053696454 | AH3: 0.00049019935 | AI3: 0.00030564389 | AJ3: 0.00058205954 | AK3: 0.00035741963 | AL3: 0.0027224019 | AM3: 0.0031065445 | AN3: 0.003346216 | AO3: 0.0046188971 | AP3: 0.0061304147 | AQ3: 0.0079609377 | AR3: 0.0082056198 | AS3: 0.0065045362 | AT3: 0.0047984421 | AU3: 0.0037328639 | AV3: 0.0035332768 | AW3: 0.0032126012 | AX3: 0.001839709 | AY3: 0.00086933139 | AZ3: 0.0015607881 | BA3: 98.522207 | BB3: 0.56475238 | BC3: 54.879968 | BD3: 110.27427 | BE3: 0.31150849 | BF3: 54.693835 | BG3: 120.19406 | BH3: 0.24586603 | BI3: 54.721179 | BJ3: 40.815531 | BK3: 1.8088755 | BL3: 49.906422 | BM3: 56.686994 | BN3: 1.6383259 | BO3: 47.92969 | BP3: 120.94511 | BQ3: 0.26728555 | BR3: 54.559764
A4: 003_Battus_crassus_crassus.png | B4: Papilionidae | C4: Battus | D4: 94236 | E4: 0.0096617947 | F4: 0.062293721 | G4: 0.0077215124 | H4: 0.0022704227 | I4: 0.0010800308 | J4: 0.00040560107 | K4: 0.0002103466 | L4: 0.00015752414 | M4: 0.00019997076 | N4: 0.00028486401 | O4: 0.00031599153 | P4: 0.0006989544 | Q4: 0.00073762799 | R4: 0.00049332409 | S4: 0.00049615386 | T4: 0.0018610486 | U4: 0.0016063394 | V4: 0.0013994121 | W4: 0.0014385426 | X4: 0.0021840114 | Y4: 0.0053860786 | Z4: 0.010276062 | AA4: 0.013033103 | AB4: 0.010191832 | AC4: 0.0066793741 | AD4: 0.0035582208 | AE4: 0.0019611666 | AF4: 0.0013907901 | AG4: 0.0010067808 | AH4: 0.00065792266 | AI4: 0.00039462095 | AJ4: 0.0013357422 | AK4: 0.0046134174 | AL4: 0.018876809 | AM4: 0.015382922 | AN4: 0.0095657445 | AO4: 0.0069028821 | AP4: 0.0030873286 | AQ4: 0.0010319835 | AR4: 0.00042778238 | AS4: 0.00029977928 | AT4: 0.00024406808 | AU4: 0.00022682414 | AV4: 0.00027059722 | AW4: 0.00029712636 | AX4: 0.00032100259 | AY4: 0.00024937391 | AZ4: 0.00070235897 | BA4: 30.434346 | BB4: 4.1042903 | BC4: 33.289888 | BD4: 40.564529 | BE4: 3.3379549 | BF4: 37.216582 | BG4: 48.682743 | BH4: 2.7597683 | BI4: 39.422159 | BJ4: 25.810147 | BK4: 3.5938373 | BL4: 32.233664 | BM4: 109.90701 | BN4: 0.59670319 | BO4: 45.487542 | BP4: 49.07408 | BQ4: 2.8379935 | BR4: 39.94757
A5: 004_Battus_crassus_lepidus.png | B5: Papilionidae | C5: Battus | D5: 107595 | E5: 0.023897021 | F5: 0.017113559 | G5: 0.0066942392 | H5: 0.021414461 | I5: 0.0032855719 | J5: 0.0013656149 | K5: 0.0010351576 | L5: 0.003706905 | M5: 0.0023412901 | N5: 0.00066091464 | O5: 0.0012730868 | P5: 0.002386728 | Q5: 0.00039737493 | R5: 0.00025858285 | S5: 0.00075013812 | T5: 0.0023082444 | U5: 0.01783424 | V5: 0.0061468934 | W5: 0.0074951206 | X5: 0.0068143269 | Y5: 0.0064576653 | Z5: 0.004898578 | AA5: 0.0035149171 | AB5: 0.0022776384 | AC5: 0.0020301826 | AD5: 0.0011437567 | AE5: 0.00053208792 | AF5: 0.00063490404 | AG5: 0.00026952925 | AH5: 0.0003810586 | AI5: 0.00010920582 | AJ5: 0.0019598959 | AK5: 0.016644012 | AL5: 0.018451717 | AM5: 0.011423626 | AN5: 0.0067109299 | AO5: 0.0034527627 | AP5: 0.0013755286 | AQ5: 0.00066685255 | AR5: 0.00045366885 | AS5: 0.00033052186 | AT5: 0.00025094103 | AU5: 0.00019517636 | AV5: 0.00017252196 | AW5: 0.00017833078 | AX5: 0.00029450718 | AY5: 0.00053150704 | AZ5: 0.0013673963 | BA5: 35.740731 | BB5: 3.101133 | BC5: 47.541196 | BD5: 39.446991 | BE5: 2.9938071 | BF5: 47.412536 | BG5: 39.679251 | BH5: 2.8442274 | BI5: 46.217922 | BJ5: 36.498741 | BK5: 1.7121232 | BL5: 41.237536 | BM5: 58.839184 | BN5: 1.4308247 | BO5: 59.194652 | BP5: 41.215661 | BQ5: 2.9196589 | BR5: 47.763136
A6: 005_Battus_ingenuus.png | B6: Papilionidae | C6: Battus | D6: 77993 | E6: 0.013900963 | F6: 0.07085992 | G6: 0.0013380118 | H6: 0.00037610213 | I6: 0.00015613937 | J6: 9.5735087e-05 | K6: 9.6874791e-05 | L6: 0.00013562471 | M6: 0.00012650708 | N6: 0.00025643327 | O6: 0.00015158055 | P6: 0.00017095551 | Q6: 0.00014588204 | R6: 0.00012194827 | S6: 0.0002347789 | T6: 0.00072143227 | U6: 0.00051847602 | V6: 0.0013310489 | W6: 0.0036573795 | X6: 0.010304611 | Y6: 0.009630672 | Z6: 0.01181356 | AA6: 0.012930648 | AB6: 0.006228123 | AC6: 0.0024753824 | AD6: 0.0012605298 | AE6: 0.00083100406 | AF6: 0.00053530445 | AG6: 0.00038785532 | AH6: 0.00019873578 | AI6: 0.00012340851 | AJ6: 0.0002732617 | AK6: 5.5293424e-05 | AL6: 0.0010946495 | AM6: 0.0015041414 | AN6: 0.0024849987 | AO6: 0.0039202236 | AP6: 0.0059652789 | AQ6: 0.0098422294 | AR6: 0.013811336 | AS6: 0.011416089 | AT6: 0.0080055261 | AU6: 0.002666906 | AV6: 0.00053370174 | AW6: 0.0003133294 | AX6: 0.00031172669 | AY6: 0.00031974023 | AZ6: 0.00025483056 | BA6: 77.343146 | BB6: 0.23347297 | BC6: 30.513791 | BD6: 95.458054 | BE6: -0.089730454 | BF6: 32.070892 | BG6: 116.12351 | BH6: -0.084741814 | BI6: 35.603364 | BJ6: 17.236444 | BK6: 6.3535917 | BL6: 20.422918 | BM6: 88.575577 | BN6: 0.96917681 | BO6: 35.364636 | BP6: 116.26849 | BQ6: -0.062814765 | BR6: 35.527065
A7: 006_Battus_ingenuus.png | B7: Papilionidae | C7: Battus | D7: 154827 | E7: 0.048273521 | F7: 0.020392079 | G7: 0.0036749261 | H7: 0.0084624918 | I7: 0.0029877074 | J7: 0.00081467272 | K7: 0.00050579751 | L7: 0.0012676514 | M7: 0.00047651752 | N7: 0.00023194347 | O7: 0.0001837176 | P7: 0.0001509929 | Q7: 7.3487039e-05 | R7: 8.8988211e-05 | S7: 0.00024974111 | T7: 0.0010546538 | U7: 0.00086184903 | V7: 0.0010749902 | W7: 0.0033137793 | X7: 0.0041788577 | Y7: 0.0057584433 | Z7: 0.0090992689 | AA7: 0.013779089 | AB7: 0.0087472631 | AC7: 0.0072601194 | AD7: 0.0042373908 | AE7: 0.0020603641 | AF7: 0.00097608944 | AG7: 0.00050459545 | AH7: 0.00024826096 | AI7: 0.00012392864 | AJ7: 0.00027571095 | AK7: 0.0044315591 | AL7: 0.013796043 | AM7: 0.0094964864 | AN7: 0.0068883334 | AO7: 0.0027357147 | AP7: 0.001458079 | AQ7: 0.0011056696 | AR7: 0.0016978628 | AS7: 0.0022234494 | AT7: 0.0023740207 | AU7: 0.0035620402 | AV7: 0.0051541398 | AW7: 0.0065653923 | AX7: 0.0010112093 | AY7: 0 | AZ7: 0 | BA7: 52.350314 | BB7: 0.68194675 | BC7: 42.657533 | BD7: 64.173394 | BE7: 0.61184885 | BF7: 49.444618 | BG7: 86.659032 | BH7: 0.55111173 | BI7: 69.462527 | BJ7: 20.037623 | BK7: 3.6763422 | BL7: 26.565626 | BM7: 103.29664 | BN7: 0.21502125 | BO7: 39.168581 | BP7: 87.680818 | BQ7: 0.54312322 | BR7: 69.272217
A8: 007_Battus_ingenuus.png | B8: Papilionidae | C8: Battus | D8: 91614 | E8: 0.004049842 | F8: 0.012444483 | G8: 0.004934714 | H8: 0.0092484652 | I8: 0.0093454906 | J8: 0.005533361 | K8: 0.007238098 | L8: 0.016134361 | M8: 0.008065725 | N8: 0.0027399985 | O8: 0.0012807358 | P8: 0.0024489222 | Q8: 0.0044292114 | R8: 0.0002852548 | S8: 0.00019599139 | T8: 0.00051423485 | U8: 0.0033360076 | V8: 0.010976079 | W8: 0.01172651 | X8: 0.013858417 | Y8: 0.0089055712 | Z8: 0.0058356256 | AA8: 0.0031040561 | AB8: 0.0015295151 | AC8: 0.0008677713 | AD8: 0.00053758159 | AE8: 0.00064741743 | AF8: 0.0006521929 | AG8: 0.00034588054 | AH8: 0.00011324688 | AI8: 3.1381667e-05 | AJ8: 3.2746087e-05 | AK8: 0.00057578536 | AL8: 0.0066522311 | AM8: 0.013071829 | AN8: 0.0094233687 | AO8: 0.0073876536 | AP8: 0.0051411356 | AQ8: 0.0049944605 | AR8: 0.0024743762 | AS8: 0.0015110955 | AT8: 0.001210923 | AU8: 0.0015479348 | AV8: 0.0025903519 | AW8: 0.0030474327 | AX8: 0.0022772175 | AY8: 0.00044684764 | AZ8: 0.00014735739 | BA8: 76.887321 | BB8: 1.1568927 | BC8: 57.154833 | BD8: 76.540343 | BE8: 1.1996218 | BF8: 50.67482 | BG8: 73.914969 | BH8: 1.0987265 | BI8: 49.211107 | BJ8: 64.048169 | BK8: 0.33429524 | BL8: 37.613991 | BM8: 58.874179 | BN8: 1.3767414 | BO8: 36.79462 | BP8: 85.636726 | BQ8: 1.0164168 | BR8: 57.381735
A9: 008_Battus_ingenuus.png | B9: Papilionidae | C9: Battus | D9: 64417 | E9: 0.0097558788 | F9: 0.045376566 | G9: 0.008494652 | H9: 0.0067890981 | I9: 0.0022851111 | J9: 0.0013964568 | K9: 0.0012391484 | L9: 0.0016324193 | M9: 0.0029681606 | N9: 0.0040334418 | O9: 0.0011121978 | P9: 0.0007534243 | Q9: 0.00024838164 | R9: 0.00018214653 | S9: 0.00047330501 | T9: 0.0021485012 | U9: 0.0071817222 | V9: 0.0070429778 | W9: 0.0086060357 | X9: 0.0069770014 | Y9: 0.0059698915 | Z9: 0.0066432386 | AA9: 0.0075242172 | AB9: 0.0048259776 | AC9: 0.0025323284 | AD9: 0.001341843 | AE9: 0.00093337163 | AF9: 0.00074320443 | AG9: 0.00062968626 | AH9: 0.00053460267 | AI9: 0.00036772125 | AJ9: 0.00064618036 | AK9: 0.00036578077 | AL9: 0.0042603272 | AM9: 0.0061367729 | AN9: 0.010493154 | AO9: 0.01482819 | AP9: 0.010223427 | AQ9: 0.007571759 | AR9: 0.0039537312 | AS9: 0.0013525156 | AT9: 0.00086157381 | AU9: 0.00074029371 | AV9: 0.00068693047 | AW9: 0.00053363243 | AX9: 0.00030950681 | AY9: 0.00013292299 | AZ9: 4.948228e-05 | BA9: 58.971824 | BB9: 1.3052949 | BC9: 34.698872 | BD9: 69.827654 | BE9: 1.2775681 | BF9: 33.435574 | BG9: 75.867116 | BH9: 0.95576763 | BI9: 35.838427 | BJ9: 35.774609 | BK9: 1.9774299 | BL9: 38.569307 | BM9: 73.871059 | BN9: 0.91337783 | BO9: 51.706091 | BP9: 78.76129 | BQ9: 1.1542293 | BR9: 36.180605
A10: 009_Battus_ingenuus.png | B10: Papilionidae | C10: Battus | D10: 122625 | E10: 0.018379431 | F10: 0.011558274 | G10: 0.0030495866 | H10: 0.020138725 | I10: 0.012630377 | J10: 0.0092241477 | K10: 0.0042630422 | L10: 0.0069588855 | M10: 0.00078867369 | N10: 0.00017904632 | O10: 0.00023268773 | P10: 4.639257e-05 | Q10: 9.6409559e-05 | R10: 0.00012685468 | S10: 0.00030300147 | T10: 0.00091335372 | U10: 0.0025463812 | V10: 0.0036167176 | W10: 0.0067273191 | X10: 0.0099429154 | Y10: 0.012478084 | Z10: 0.010417941 | AA10: 0.0061029562 | AB10: 0.0029011213 | AC10: 0.0026712538 | AD10: 0.0015820591 | AE10: 0.00090366972 | AF10: 0.00079204893 | AG10: 0.00034250765 | AH10: 0.00035524975 | AI10: 0.00017431193 | AJ10: 0.00094546381 | AK10: 0.0088430173 | AL10: 0.019102956 | AM10: 0.010572885 | AN10: 0.0048858308 | AO10: 0.0022283384 | AP10: 0.0018639144 | AQ10: 0.001716106 | AR10: 0.0010856269 | AS10: 0.00063659531 | AT10: 0.00044801223 | AU10: 0.00042711519 | AV10: 0.00072833843 | AW10: 0.0013848114 | AX10: 0.0034678899 | AY10: 0.0041151886 | AZ10: 0.00099337411 | BA10: 51.944334 | BB10: 1.4795672 | BC10: 56.202019 | BD10: 60.921753 | BE10: 1.3305745 | BF10: 59.366036 | BG10: 65.26577 | BH10: 1.4148828 | BI10: 74.084185 | BJ10: 39.70135 | BK10: 1.2401376 | BL10: 30.595925 | BM10: 79.830793 | BN10: 1.263959 | BO10: 45.430148 | BP10: 70.650952 | BQ10: 1.3122332 | BR10: 74.198675
A11: 010_Battus_ingenuus.png | B11: Papilionidae | C11: Battus | D11: 140102 | E11: 0.0037934267 | F11: 0.013782974 | G11: 0.012437922 | H11: 0.031975434 | I11: 0.015360238 | J11: 0.0047368663 | K11: 0.0038460867 | L11: 0.0017390504 | M11: 0.00028487182 | N11: 0.00010532009 | O11: 0.00016115243 | P11: 0.00010595455 | Q11: 0.00010468563 | R11: 7.6769465e-05 | S11: 0.00014465651 | T11: 0.00023348069 | U11: 0.0012419523 | V11: 0.0039100976 | W11: 0.0068173545 | X11: 0.0071590698 | Y11: 0.0070140862 | Z11: 0.0057475982 | AA11: 0.0043807369 | AB11: 0.0035978252 | AC11: 0.003722288 | AD11: 0.0057734722 | AE11: 0.0055945847 | AF11: 0.0023514118 | AG11: 0.0010108707 | AH11: 0.0005897489 | AI11: 0.00035688284 | AJ11: 0.0032320202 | AK11: 0.0037428088 | AL11: 0.0036883842 | AM11: 0.0045761302 | AN11: 0.0046845334 | AO11: 0.0039480164 | AP11: 0.0031071112 | AQ11: 0.00301566 | AR11: 0.0029050263 | AS11: 0.0028729069 | AT11: 0.0028666614 | AU11: 0.0028180361 | AV11: 0.0025097786 | AW11: 0.0022974333 | AX11: 0.0032199754 | AY11: 0.0059126565 | AZ11: 0.010334881 | BA11: 83.229725 | BB11: 0.54752143 | BC11: 56.89557 | BD11: 135.848 | BE11: -0.0081207118 | BF11: 84.269104 | BG11: 115.62215 | BH11: 0.1380609 | BI11: 72.349378 | BJ11: 39.621033 | BK11: 1.7276732 | BL11: 20.251873 | BM11: 106.06385 | BN11: 0.60438025 | BO11: 62.193578 | BP11: 138.07014 | BQ11: -0.027110525 | BR11: 83.746999
A12: 011_Battus_ingenuus.png | B12: Papilionidae | C12: Battus | D12: 88144 | E12: 0.0045531554 | F12: 0.064729433 | G12: 0.011019342 | H12: 0.0033692342 | I12: 0.0010467719 | J12: 0.00052439443 | K12: 0.00036606765 | L12: 0.00034388173 | M12: 0.00034892398 | N12: 0.00045985357 | O12: 0.0003751437 | P12: 0.00025513806 | Q12: 0.00016941974 | R12: 0.00011092959 | S12: 0.00027833243 | T12: 0.00093886771 | U12: 0.002149182 | V12: 0.0075707082 | W12: 0.011055772 | X12: 0.0083024653 | Y12: 0.0079833851 | Z12: 0.010303452 | AA12: 0.0080018209 | AB12: 0.0031666931 | AC12: 0.0012997198 | AD12: 0.0007452294 | AE12: 0.00049280155 | AF12: 0.00034673375 | AG12: 0.00026164572 | AH12: 0.00018719368 | AI12: 0.00012125045 | AJ12: 0.00051194636 | AK12: 0.00039991378 | AL12: 0.0018052845 | AM12: 0.0019655337 | AN12: 0.0018215931 | AO12: 0.0024838616 | AP12: 0.003524772 | AQ12: 0.0045933359 | AR12: 0.006203627 | AS12: 0.0067155734 | AT12: 0.0075558178 | AU12: 0.0086541625 | AV12: 0.0086392721 | AW12: 0.0049074526 | AX12: 0.0015606564 | AY12: 0.00060483414 | AZ12: 0.0010643095 | BA12: 103.45258 | BB12: 0.13365454 | BC12: 45.781632 | BD12: 125.49184 | BE12: -0.24480257 | BF12: 48.342298 | BG12: 139.30007 | BH12: -0.48825103 | BI12: 51.091821 | BJ12: 24.417601 | BK12: 4.6241827 | BL12: 23.743025 | BM12: 71.304173 | BN12: 1.2492922 | BO12: 40.798909 | BP12: 139.84131 | BQ12: -0.46524425 | BR12: 50.850037
A13: 012_Battus_laodamas_laodamas.png | B13: Papilionidae | C13: Battus | D13: 148803 | E13: 0.0014282866 | F13: 0.074708171 | G13: 0.012335474 | H13: 0.00035542892 | I13: 2.0907583e-05 | J13: 5.9735952e-07 | K13: 2.3894381e-06 | L13: 2.3894381e-06 | M13: 0 | N13: 0 | O13: 0 | P13: 0 | Q13: 0 | R13: 0 | S13: 5.9735952e-06 | T13: 2.9270617e-05 | U13: 1.2600552e-06 | V13: 4.6202025e-06 | W13: 2.646116e-05 | X13: 9.4084125e-05 | Y13: 0.00023605035 | Z13: 0.00060272642 | AA13: 0.0014297427 | AB13: 0.0029712103 | AC13: 0.0053237334 | AD13: 0.0092223443 | AE13: 0.013118435 | AF13: 0.012943287 | AG13: 0.008325185 | AH13: 0.0047504083 | AI13: 0.0020715308 | AJ13: 0.0013789205 | AK13: 0.00013818606 | AL13: 0.0041413816 | AM13: 0.025414894 | AN13: 0.016444561 | AO13: 0.0085108331 | AP13: 0.0031602185 | AQ13: 0.0013738802 | AR13: 0.0010202247 | AS13: 0.0014175621 | AT13: 0.00085473747 | AU13: 2.2260976e-05 | AV13: 1.2600552e-06 | AW13: 0 | AX13: 0 | AY13: 0 | AZ13: 0 | BA13: 17.681115 | BB13: 2.2127857 | BC13: 10.87812 | BD13: 41.291728 | BE13: 1.9580303 | BF13: 21.162145 | BG13: 55.536172 | BH13: 1.7294092 | BI13: 25.437599 | BJ13: 18.471039 | BK13: 10.42508 | BL13: 5.275536 | BM13: 172.64254 | BN13: -0.21698392 | BO13: 32.682728 | BP13: 55.558255 | BQ13: 1.7323071 | BR13: 25.420309
... A813: 534_Tatochila_xanthodice_xanthodice.png | B813: Pieridae | C813: Tatochila | D813: 57906 | E813: 0.0071149794 | F813: 0.016535611 | G813: 0.019232703 | H813: 0.010576528 | I813: 0.0070704629 | J813: 0.0040417995 | K813: 0.0042398216 | L813: 0.0054433047 | M813: 0.0069430533 | N813: 0.002321003 | O813: 0.00063244262 | P813: 0.00056643526 | Q813: 0.00055568987 | R813: 0.00054647954 | S813: 0.0010085311 | T813: 0.0020600437 | U813: 0.0039525265 | V813: 0.01261959 | W813: 0.011262866 | X813: 0.0080313353 | Y813: 0.0054700722 | Z813: 0.0036848513 | AA813: 0.0028850637 | AB813: 0.0024382188 | AC813: 0.0024090768 | AD813: 0.0023702207 | AE813: 0.0023281266 | AF813: 0.0020226747 | AG813: 0.0014635789 | AH813: 0.00086454772 | AI813: 0.00042849618 | AJ813: 0.00026875453 | AK813: 0 | AL813: 1.2952026e-05 | AM813: 0.00037345007 | AN813: 0.0011851104 | AO813: 0.0020194367 | AP813: 0.0049055797 | AQ813: 0.0065062342 | AR813: 0.0068926363 | AS813: 0.0069379684 | AT813: 0.0068937157 | AU813: 0.0063821107 | AV813: 0.0058705056 | AW813: 0.0056136238 | AX813: 0.0062525904 | AY813: 0.0024770749 | AZ813: 0.00017701102 | BA813: 111.702 | BB813: 0.079081547 | BC813: 52.97602 | BD813: 141.43398 | BE813: -0.078491488 | BF813: 51.371145 | BG813: 141.23861 | BH813: -0.081521759 | BI813: 41.343226 | BJ813: 49.255552 | BK813: 1.3554579 | BL813: 38.943042 | BM813: 73.794218 | BN813: 1.0481185 | BO813: 56.5702 | BP813: 149.86252 | BQ813: -0.053304031 | BR813: 46.473967

Sheet Datos_Textura
A1: filename | B1: familia | C1: genero | D1: fg_pixels | E1: gabor_f0.1_t0_mean | F1: gabor_f0.1_t0_std | G1: gabor_f0.1_t135_mean | H1: gabor_f0.1_t135_std | I1: gabor_f0.1_t45_mean | J1: gabor_f0.1_t45_std | K1: gabor_f0.1_t90_mean | L1: gabor_f0.1_t90_std | M1: gabor_f0.2_t0_mean | N1: gabor_f0.2_t0_std | O1: gabor_f0.2_t135_mean | P1: gabor_f0.2_t135_std | Q1: gabor_f0.2_t45_mean | R1: gabor_f0.2_t45_std | S1: gabor_f0.2_t90_mean | T1: gabor_f0.2_t90_std | U1: gabor_f0.3_t0_mean | V1: gabor_f0.3_t0_std | W1: gabor_f0.3_t135_mean | X1: gabor_f0.3_t135_std | Y1: gabor_f0.3_t45_mean | Z1: gabor_f0.3_t45_std | AA1: gabor_f0.3_t90_mean | AB1: gabor_f0.3_t90_std | AC1: gabor_f0.4_t0_mean | AD1: gabor_f0.4_t0_std | AE1: gabor_f0.4_t135_mean | AF1: gabor_f0.4_t135_std | AG1: gabor_f0.4_t45_mean | AH1: gabor_f0.4_t45_std | AI1: gabor_f0.4_t90_mean | AJ1: gabor_f0.4_t90_std | AK1: glcm_ASM_d1_mean | AL1: glcm_ASM_d1_std | AM1: glcm_ASM_d2_mean | AN1: glcm_ASM_d2_std | AO1: glcm_ASM_d3_mean | AP1: glcm_ASM_d3_std | AQ1: glcm_contrast_d1_mean | AR1: glcm_contrast_d1_std | AS1: glcm_contrast_d2_mean | AT1: glcm_contrast_d2_std | AU1: glcm_contrast_d3_mean | AV1: glcm_contrast_d3_std | AW1: glcm_correlation_d1_mean | AX1: glcm_correlation_d1_std | AY1: glcm_correlation_d2_mean | AZ1: glcm_correlation_d2_std | BA1: glcm_correlation_d3_mean | BB1: glcm_correlation_d3_std | BC1: glcm_dissimilarity_d1_mean | BD1: glcm_dissimilarity_d1_std | BE1: glcm_dissimilarity_d2_mean | BF1: glcm_dissimilarity_d2_std | BG1: glcm_dissimilarity_d3_mean | BH1: glcm_dissimilarity_d3_std | BI1: glcm_energy_d1_mean | BJ1: glcm_energy_d1_std | BK1: glcm_energy_d2_mean | BL1: glcm_energy_d2_std | BM1: glcm_energy_d3_mean | BN1: glcm_energy_d3_std | BO1: glcm_homogeneity_d1_mean | BP1: glcm_homogeneity_d1_std | BQ1: glcm_homogeneity_d2_mean | BR1: glcm_homogeneity_d2_std | BS1: glcm_homogeneity_d3_mean | BT1: glcm_homogeneity_d3_std | BU1: haralick_angular_second_moment | BV1: haralick_contrast | BW1: haralick_correlation | BX1: haralick_difference_entropy | BY1: haralick_difference_variance | BZ1: haralick_entropy | CA1: haralick_info_measure_corr_1 | CB1: haralick_info_measure_corr_2 | CC1: haralick_inverse_diff_moment | CD1: haralick_sum_average | CE1: haralick_sum_entropy | CF1: haralick_sum_variance | CG1: haralick_variance
A2: 001_Battus_crassus_crassus.png | B2: Papilionidae | C2: Battus | D2: 82002 | E2: 0.0042951507 | F2: 0.0055080337 | G2: 0.0060976976 | H2: 0.012752663 | I2: 0.0072948507 | J2: 0.015408418 | K2: 0.0045234581 | L2: 0.0091875049 | M2: 0.0039607048 | N2: 0.0053112458 | O2: 0.004859245 | P2: 0.010411032 | Q2: 0.005386015 | R2: 0.011660549 | S2: 0.0041843517 | T2: 0.010373306 | U2: 0.0039821469 | V2: 0.0059967642 | W2: 0.0045952138 | X2: 0.0096552745 | Y2: 0.0048764752 | Z2: 0.010489645 | AA2: 0.0042422966 | AB2: 0.0093523489 | AC2: 0.0041054761 | AD2: 0.0072637956 | AE2: 0.0042404683 | AF2: 0.0088475725 | AG2: 0.004413356 | AH2: 0.0091814466 | AI2: 0.0042579938 | AJ2: 0.0089642157 | AK2: 0.1347717 | AL2: 0.010372469 | AM2: 0.12159429 | AN2: 0.0051213668 | AO2: 0.10605741 | AP2: 0.0037010791 | AQ2: 5.7176446 | AR2: 1.0743995 | AS2: 8.0229112 | AT2: 1.4297063 | AU2: 12.11406 | AV2: 1.1555085 | AW2: 0.91542979 | AX2: 0.015841868 | AY2: 0.8815062 | AZ2: 0.021042433 | BA2: 0.82166408 | BB2: 0.017064958 | BC2: 0.94966232 | BD2: 0.094312294 | BE2: 1.1289644 | BF2: 0.088149681 | BG2: 1.402916 | BH2: 0.05089737 | BI2: 0.36684351 | BJ2: 0.014055083 | BK2: 0.34862451 | BL2: 0.007432152 | BM2: 0.32561557 | BN2: 0.0056496217 | BO2: 0.73982298 | BP2: 0.0219076 | BQ2: 0.70858396 | BR2: 0.014021218 | BS2: 0.66773458 | BT2: 0.010631523 | BU2: 0.005042422 | BV2: 358.85837 | BW2: 0.91692449 | BX2: 4.0329084 | BY2: 0.00046793175 | BZ2: 9.909483 | CA2: -0.27088305 | CB2: 0.97554568 | CC2: 0.36769946 | CD2: 70.699395 | CE2: 6.635285 | CF2: 8279.3738 | CG2: 2159.558
A3: 002_Battus_crassus_crassus.png | B3: Papilionidae | C3: Battus | D3: 74842 | E3: 0.011381004 | F3: 0.01052549 | G3: 0.016505973 | H3: 0.011745508 | I3: 0.011830225 | J3: 0.012757329 | K3: 0.018063194 | L3: 0.019006928 | M3: 0.010952954 | N3: 0.0093175474 | O3: 0.012321061 | P3: 0.0093891282 | Q3: 0.010015653 | R3: 0.0082516317 | S3: 0.012429761 | T3: 0.013133796 | U3: 0.010691348 | V3: 0.0083759116 | W3: 0.010955997 | X3: 0.0083435589 | Y3: 0.0096495706 | Z3: 0.0070030382 | AA3: 0.010154787 | AB3: 0.0092088895 | AC3: 0.0091339521 | AD3: 0.0081523935 | AE3: 0.008707627 | AF3: 0.007063638 | AG3: 0.0079877579 | AH3: 0.0061474135 | AI3: 0.0080713371 | AJ3: 0.0076512169 | AK3: 0.005058333 | AL3: 0.00062011493 | AM3: 0.0041623409 | AN3: 0.00033623637 | AO3: 0.0034224493 | AP3: 0.00017992814 | AQ3: 9.8655359 | AR3: 2.4794943 | AS3: 14.906367 | AT3: 3.0826853 | AU3: 24.592232 | AV3: 2.8735943 | AW3: 0.89105756 | AX3: 0.027363774 | AY3: 0.83539405 | AZ3: 0.034124016 | BA3: 0.72828721 | BB3: 0.032141445 | BC3: 2.1660123 | BD3: 0.29675867 | BE3: 2.6815856 | BF3: 0.26358078 | BG3: 3.4235062 | BH3: 0.21330719 | BI3: 0.070986568 | BJ3: 0.0043863572 | BK3: 0.064463832 | BL3: 0.0025990905 | BM3: 0.05848145 | BN3: 0.0015392268 | BO3: 0.40476186 | BP3: 0.036749815 | BQ3: 0.34987048 | BR3: 0.021369794 | BS3: 0.29785831 | BT3: 0.013162691 | BU3: 9.2947398e-05 | BV3: 621.6911 | BW3: 0.89271066 | BX3: 5.5713467 | BY3: 9.5953142e-05 | BZ3: 13.923978 | CA3: -0.19264925 | CB3: 0.97244122 | CC3: 0.07864968 | CD3: 223.79176 | CE3: 8.6613693 | CF3: 10966.8 | CG3: 2897.1227
A4: 003_Battus_crassus_crassus.png | B4: Papilionidae | C4: Battus | D4: 94236 | E4: 0.0058322728 | F4: 0.0096707611 | G4: 0.006748743 | H4: 0.0092792104 | I4: 0.0076430225 | J4: 0.010726737 | K4: 0.0091697472 | L4: 0.0094573346 | M4: 0.0039202605 | N4: 0.0061613192 | O4: 0.0043013467 | P4: 0.0059029869 | Q4: 0.0048650973 | R4: 0.0068156506 | S4: 0.0050068663 | T4: 0.0056115219 | U4: 0.0029110997 | V4: 0.0046904295 | W4: 0.0031224235 | X4: 0.0043764743 | Y4: 0.0033868199 | Z4: 0.0049935096 | AA4: 0.0034519729 | AB4: 0.0038917181 | AC4: 0.0023201545 | AD4: 0.0040751831 | AE4: 0.0023170489 | AF4: 0.003588188 | AG4: 0.0024010537 | AH4: 0.0038345416 | AI4: 0.0025599289 | AJ4: 0.003180827 | AK4: 0.044301926 | AL4: 0.006253701 | AM4: 0.036854727 | AN4: 0.0040618117 | AO4: 0.028594651 | AP4: 0.0029708716 | AQ4: 2.266973 | AR4: 0.59205012 | AS4: 3.713697 | AT4: 0.9178571 | AU4: 7.2700948 | AV4: 0.72439041 | AW4: 0.94658315 | AX4: 0.014037141 | AY4: 0.91235388 | AZ4: 0.021794577 | BA4: 0.82751482 | BB4: 0.018256286 | BC4: 0.77154622 | BD4: 0.12737427 | BE4: 1.0050411 | BF4: 0.15118549 | BG4: 1.438339 | BH4: 0.13670504 | BI4: 0.20998141 | BJ4: 0.014482222 | BK4: 0.19166288 | BL4: 0.010957455 | BM4: 0.16887286 | BN4: 0.008752527 | BO4: 0.71071765 | BP4: 0.041115478 | BQ4: 0.6532538 | BR4: 0.04066297 | BS4: 0.5671845 | BT4: 0.038991135 | BU4: 0.00096999559 | BV4: 135.6646 | BW4: 0.94995305 | BX4: 4.0468059 | BY4: 0.00035399902 | BZ4: 11.173732 | CA4: -0.28052725 | CB4: 0.98524108 | CC4: 0.24739505 | CD4: 83.342577 | CE4: 7.4652787 | CF4: 5287.8871 | CG4: 1355.8879
A5: 004_Battus_crassus_lepidus.png | B5: Papilionidae | C5: Battus | D5: 107595 | E5: 0.006727176 | F5: 0.0067426407 | G5: 0.0081657529 | H5: 0.011720034 | I5: 0.0068650474 | J5: 0.0092709824 | K5: 0.0071321156 | L5: 0.007912438 | M5: 0.0069319562 | N5: 0.0070780398 | O5: 0.0077075982 | P5: 0.0094406497 | Q5: 0.0069218721 | R5: 0.0083069839 | S5: 0.0071472295 | T5: 0.0082515698 | U5: 0.0073985436 | V5: 0.0079348832 | W5: 0.0079480908 | X5: 0.0096722027 | Y5: 0.0075765324 | Z5: 0.0093291007 | AA5: 0.0078053856 | AB5: 0.0092429842 | AC5: 0.0075130257 | AD5: 0.0093846412 | AE5: 0.0076658367 | AF5: 0.010010892 | AG5: 0.0075573789 | AH5: 0.010037397 | AI5: 0.0078219617 | AJ5: 0.010615795 | AK5: 0.028851855 | AL5: 0.002674817 | AM5: 0.02536529 | AN5: 0.00082372042 | AO5: 0.022587538 | AP5: 0.00021028392 | AQ5: 9.0184377 | AR5: 1.1751578 | AS5: 11.302806 | AT5: 1.295518 | AU5: 14.891715 | AV5: 0.80163452 | AW5: 0.86936643 | AX5: 0.016978292 | AY5: 0.83638892 | AZ5: 0.018633186 | BA5: 0.78486359 | BB5: 0.01134796 | BC5: 1.5993794 | BD5: 0.13465739 | BE5: 1.8232232 | BF5: 0.093543754 | BG5: 2.1045999 | BH5: 0.028794715 | BI5: 0.16967532 | BJ5: 0.007883065 | BK5: 0.15924386 | BL5: 0.0025850859 | BM5: 0.15028987 | BN5: 0.00070129848 | BO5: 0.55861888 | BP5: 0.027780428 | BQ5: 0.51890807 | BR5: 0.011950971 | BS5: 0.47945927 | BT5: 0.0018370384 | BU5: 0.00072712539 | BV5: 572.3974 | BW5: 0.87029843 | BX5: 5.0687871 | BY5: 0.00017804048 | BZ5: 11.971666 | CA5: -0.16493689 | CB5: 0.93809756 | CC5: 0.16976459 | CD5: 77.859512 | CE5: 7.482654 | CF5: 8253.5304 | CG5: 2206.482
A6: 005_Battus_ingenuus.png | B6: Papilionidae | C6: Battus | D6: 77993 | E6: 0.0070609435 | F6: 0.0089719167 | G6: 0.0097174661 | H6: 0.0094541784 | I6: 0.007657159 | J6: 0.0091938268 | K6: 0.012836529 | L6: 0.011008754 | M6: 0.0055069985 | N6: 0.0059993807 | O6: 0.0076257683 | P6: 0.007878138 | Q6: 0.006229024 | R6: 0.0066252216 | S6: 0.0094014519 | T6: 0.009035366 | U6: 0.0048289886 | V6: 0.0051775376 | W6: 0.0062094476 | X6: 0.0063983366 | Y6: 0.0053806797 | Z6: 0.0053225896 | AA6: 0.0074993497 | AB6: 0.0074888089 | AC6: 0.0041179963 | AD6: 0.0050937934 | AE6: 0.0048089852 | AF6: 0.0051220847 | AG6: 0.0043976869 | AH6: 0.0046263168 | AI6: 0.0059714595 | AJ6: 0.0065301149 | AK6: 0.016195513 | AL6: 0.0030953383 | AM6: 0.013189891 | AN6: 0.0015536649 | AO6: 0.010427306 | AP6: 0.0012468314 | AQ6: 4.3631541 | AR6: 1.1077519 | AS6: 6.5108334 | AT6: 1.4833704 | AU6: 10.80036 | AV6: 1.1627186 | AW6: 0.86658479 | AX6: 0.033914681 | AY6: 0.80070184 | AZ6: 0.045604903 | BA6: 0.66866006 | BB6: 0.03613702 | BC6: 1.2944181 | BD6: 0.20943759 | BE6: 1.6150734 | BF6: 0.21266647 | BG6: 2.1253809 | BH6: 0.18774718 | BI6: 0.12672282 | BJ6: 0.0116979 | BK6: 0.11463391 | BL6: 0.0069969804 | BM6: 0.10193477 | BN6: 0.0060505545 | BO6: 0.56535372 | BP6: 0.049602721 | BQ6: 0.50451748 | BR6: 0.036889274 | BS6: 0.43008634 | BT6: 0.033257979 | BU6: 0.00028987276 | BV6: 268.62116 | BW6: 0.87094325 | BX6: 4.8181088 | BY6: 0.00019233763 | BZ6: 12.538749 | CA6: -0.21037831 | CB6: 0.97042305 | CC6: 0.14016462 | CD6: 199.14763 | CE6: 7.956639 | CF6: 3894.5908 | CG6: 1040.803
A7: 006_Battus_ingenuus.png | B7: Papilionidae | C7: Battus | D7: 154827 | E7: 0.005166437 | F7: 0.0082516631 | G7: 0.0047506325 | H7: 0.0082466971 | I7: 0.0048505262 | J7: 0.0085868483 | K7: 0.0045459378 | L7: 0.0058685133 | M7: 0.0031864638 | N7: 0.0045759598 | O7: 0.0030329561 | P7: 0.005544353 | Q7: 0.0030505601 | R7: 0.0060700379 | S7: 0.0031503776 | T7: 0.0045305218 | U7: 0.0024635248 | V7: 0.0036965057 | W7: 0.0022386511 | X7: 0.0039221741 | Y7: 0.0022556388 | Z7: 0.0040405206 | AA7: 0.0024839495 | AB7: 0.0037426273 | AC7: 0.002085597 | AD7: 0.0032682059 | AE7: 0.0017419407 | AF7: 0.0029128043 | AG7: 0.0017342998 | AH7: 0.0029266302 | AI7: 0.002068955 | AJ7: 0.0033055176 | AK7: 0.039597042 | AL7: 0.0031678336 | AM7: 0.034867698 | AN7: 0.0015798727 | AO7: 0.028870301 | AP7: 0.00028200373 | AQ7: 1.4592778 | AR7: 0.36944082 | AS7: 2.3424267 | AT7: 0.55561527 | AU7: 4.4935677 | AV7: 0.43046356 | AW7: 0.98413526 | AX7: 0.004012262 | AY7: 0.97455379 | AZ7: 0.0060190008 | BA7: 0.95125483 | BB7: 0.0046279607 | BC7: 0.53413619 | BD7: 0.083249271 | BE7: 0.69489553 | BF7: 0.083596658 | BG7: 1.0031275 | BH7: 0.046087043 | BI7: 0.19883059 | BJ7: 0.0079649696 | BK7: 0.18668095 | BL7: 0.0042334484 | BM7: 0.16991061 | BN7: 0.00082790794 | BO7: 0.79563775 | BP7: 0.026078391 | BQ7: 0.75151274 | BR7: 0.019300967 | BS7: 0.67919721 | BT7: 0.0086380634 | BU7: 0.0016988517 | BV7: 85.018314 | BW7: 0.98552076 | BX7: 3.5115703 | BY7: 0.00066376721 | BZ7: 11.067114 | CA7: -0.42514125 | CB7: 0.99858882 | CC7: 0.37756413 | CD7: 139.14072 | CE7: 7.9946443 | CF7: 11657.49 | CG7: 2935.6272
A8: 007_Battus_ingenuus.png | B8: Papilionidae | C8: Battus | D8: 91614 | E8: 0.008326811 | F8: 0.010414793 | G8: 0.0081099137 | H8: 0.0091010194 | I8: 0.0072381829 | J8: 0.0086667965 | K8: 0.0070574586 | L8: 0.0072393351 | M8: 0.0051172298 | N8: 0.0066717342 | O8: 0.0047652781 | P8: 0.0057684098 | Q8: 0.0046922676 | R8: 0.0064777781 | S8: 0.0042973854 | T8: 0.0047307764 | U8: 0.004314737 | V8: 0.0055414843 | W8: 0.0038577288 | X8: 0.0041703452 | Y8: 0.0038805638 | Z8: 0.0047911932 | AA8: 0.0038045575 | AB8: 0.0037443927 | AC8: 0.0037767815 | AD8: 0.0053363429 | AE8: 0.0029699767 | AF8: 0.0032354571 | AG8: 0.0030043407 | AH8: 0.0036118403 | AI8: 0.0031277445 | AJ8: 0.0034023853 | AK8: 0.02255263 | AL8: 0.0026886842 | AM8: 0.018805399 | AN8: 0.001277347 | AO8: 0.014997612 | AP8: 0.00052606239 | AQ8: 2.5435559 | AR8: 0.65594791 | AS8: 3.9428505 | AT8: 0.88439796 | AU8: 7.2872178 | AV8: 0.70205262 | AW8: 0.9671054 | AX8: 0.0084749642 | AY8: 0.94905701 | AZ8: 0.011429831 | BA8: 0.90604981 | BB8: 0.0091138697 | BC8: 0.89952177 | BD8: 0.13414832 | BE8: 1.137421 | BF8: 0.11337662 | BG8: 1.5621778 | BH8: 0.058517139 | BI8: 0.14990943 | BJ8: 0.0089327569 | BK8: 0.13705259 | BL8: 0.0046889355 | BM8: 0.12244592 | BN8: 0.0021470674 | BO8: 0.66912088 | BP8: 0.035502382 | BQ8: 0.61496617 | BR8: 0.01903978 | BS8: 0.54375903 | BT8: 0.0030923377 | BU8: 0.00046898575 | BV8: 152.73744 | BW8: 0.96905266 | BX8: 4.2946375 | BY8: 0.00031554614 | BZ8: 12.167629 | CA8: -0.32055613 | CB8: 0.99478918 | CC8: 0.2128137 | CD8: 151.53394 | CE8: 8.2310316 | CF8: 9717.5668 | CG8: 2467.5761
A9: 008_Battus_ingenuus.png | B9: Papilionidae | C9: Battus | D9: 64417 | E9: 0.008644589 | F9: 0.011400191 | G9: 0.011632515 | H9: 0.010328232 | I9: 0.0090638764 | J9: 0.013108891 | K9: 0.0099488965 | L9: 0.009887636 | M9: 0.0061105133 | N9: 0.007912698 | O9: 0.0075143498 | P9: 0.0079265394 | Q9: 0.0062789759 | R9: 0.0088952332 | S9: 0.0068369292 | T9: 0.0074854648 | U9: 0.0052348093 | V9: 0.0064219387 | W9: 0.0057687001 | X9: 0.0059103202 | Y9: 0.0050937602 | Z9: 0.006157223 | AA9: 0.0059279939 | AB9: 0.0058353304 | AC9: 0.0045786873 | AD9: 0.0061144558 | AE9: 0.0043631943 | AF9: 0.0045523623 | AG9: 0.0040463671 | AH9: 0.0046486182 | AI9: 0.0047744748 | AJ9: 0.0050777864 | AK9: 0.018413898 | AL9: 0.0024456169 | AM9: 0.01511217 | AN9: 0.0014029504 | AO9: 0.011969793 | AP9: 0.00073631324 | AQ9: 4.292569 | AR9: 1.0396769 | AS9: 6.6075156 | AT9: 1.2834565 | AU9: 11.657152 | AV9: 0.41169845 | AW9: 0.87446574 | AX9: 0.030531282 | AY9: 0.80623019 | AZ9: 0.037892233 | BA9: 0.65642825 | BB9: 0.011962635 | BC9: 1.2286495 | BD9: 0.17150681 | BE9: 1.5465164 | BF9: 0.16155712 | BG9: 2.0781509 | BH9: 0.08315506 | BI9: 0.13539995 | BJ9: 0.0089861987 | BK9: 0.12279844 | BL9: 0.0057195612 | BM9: 0.10935491 | BN9: 0.0033608647 | BO9: 0.58448023 | BP9: 0.0401419 | BQ9: 0.5246437 | BR9: 0.029140417 | BS9: 0.45166003 | BT9: 0.020194934 | BU9: 0.00033606735 | BV9: 264.07578 | BW9: 0.8787045 | BX9: 4.7282063 | BY9: 0.00020905545 | BZ9: 12.318536 | CA9: -0.22531145 | CB9: 0.97622579 | CC9: 0.15039374 | CD9: 140.67052 | CE9: 7.9013549 | CF9: 4091.4369 | CG9: 1088.8782
A10: 009_Battus_ingenuus.png | B10: Papilionidae | C10: Battus | D10: 122625 | E10: 0.0074667249 | F10: 0.011254128 | G10: 0.0052702237 | H10: 0.0082188687 | I10: 0.0062377905 | J10: 0.010612312 | K10: 0.0055950406 | L10: 0.0071585332 | M10: 0.0054258912 | N10: 0.00768593 | O10: 0.0045123694 | P10: 0.0059857757 | Q10: 0.0046643796 | R10: 0.0064194354 | S10: 0.0048973039 | T10: 0.0059232271 | U10: 0.0043405832 | V10: 0.0061217144 | W10: 0.0039268327 | X10: 0.0051261182 | Y10: 0.0039418087 | Z10: 0.0049778694 | AA10: 0.0045604848 | AB10: 0.0055026237 | AC10: 0.0035555537 | AD10: 0.0055557417 | AE10: 0.0031366228 | AF10: 0.0043573289 | AG10: 0.0031355443 | AH10: 0.004145318 | AI10: 0.0038598322 | AJ10: 0.0053330648 | AK10: 0.035544777 | AL10: 0.0037541221 | AM10: 0.030393642 | AN10: 0.0016720137 | AO10: 0.025403576 | AP10: 0.00058526878 | AQ10: 2.7894121 | AR10: 0.69857522 | AS10: 4.2258153 | AT10: 0.82589793 | AU10: 7.4524233 | AV10: 0.68715115 | AW10: 0.97741088 | AX10: 0.0056584412 | AY10: 0.96578531 | AZ10: 0.0066630464 | BA10: 0.93967514 | BB10: 0.0054745369 | BC10: 0.85109443 | BD10: 0.12235249 | BE10: 1.0603416 | BF10: 0.092012212 | BG10: 1.3999057 | BH10: 0.055667611 | BI10: 0.18827165 | BJ10: 0.00992791 | BK10: 0.17427123 | BL10: 0.0048146746 | BM10: 0.15937443 | BN10: 0.0018353871 | BO10: 0.69348382 | BP10: 0.032713827 | BQ10: 0.64499 | BR10: 0.015906625 | BS10: 0.5850995 | BT10: 0.0039889093 | BU10: 0.00083272137 | BV10: 168.74001 | BW10: 0.97861975 | BX10: 4.1895742 | BY10: 0.00033291387 | BZ10: 11.730687 | CA10: -0.32442467 | CB10: 0.99421965 | CC10: 0.25201332 | CD10: 122.23191 | CE10: 7.9714216 | CF10: 15615.988 | CG10: 3946.1821
A11: 010_Battus_ingenuus.png | B11: Papilionidae | C11: Battus | D11: 140102 | E11: 0.014175525 | F11: 0.014289884 | G11: 0.011062211 | H11: 0.011365161 | I11: 0.013228157 | J11: 0.013866169 | K11: 0.010859901 | L11: 0.011491918 | M11: 0.012258403 | N11: 0.012578611 | O11: 0.011189501 | P11: 0.011764193 | Q11: 0.011809811 | R11: 0.012416483 | S11: 0.010724519 | T11: 0.010787655 | U11: 0.012842657 | V11: 0.012714726 | W11: 0.012548826 | X11: 0.012958008 | Y11: 0.012731392 | Z11: 0.0130263 | AA11: 0.012298955 | AB11: 0.01176383 | AC11: 0.014209381 | AD11: 0.014890388 | AE11: 0.013997248 | AF11: 0.014806184 | AG11: 0.014235014 | AH11: 0.015058737 | AI11: 0.014035842 | AJ11: 0.014683368 | AK11: 0.004996395 | AL11: 0.00042631282 | AM11: 0.0043785566 | AN11: 0.00024088351 | AO11: 0.0036972256 | AP11: 0.00012052564 | AQ11: 23.789828 | AR11: 2.0210615 | AS11: 27.920077 | AT11: 2.5674919 | AU11: 35.450096 | AV11: 1.8407695 | AW11: 0.86759586 | AX11: 0.011229237 | AY11: 0.84463426 | AZ11: 0.014285489 | BA11: 0.80282544 | BB11: 0.01026857 | BC11: 3.0376467 | BD11: 0.16331493 | BE11: 3.3425224 | BF11: 0.16362718 | BG11: 3.8497159 | BH11: 0.10565864 | BI11: 0.070621227 | BJ11: 0.0030062139 | BK11: 0.066145288 | BL11: 0.0018323432 | BM11: 0.060796718 | BN11: 0.00099230159 | BO11: 0.41137968 | BP11: 0.020299633 | BQ11: 0.37909352 | BR11: 0.013402451 | BS11: 0.33744582 | BT11: 0.0064327005 | BU11: 0.00017980575 | BV11: 1515.2381 | BW11: 0.86833551 | BX11: 5.9947581 | BY11: 8.9741061e-05 | BZ11: 14.328491 | CA11: -0.18841136 | CB11: 0.97379823 | CC11: 0.11350835 | CD11: 247.50349 | CE11: 8.9200888 | CF11: 21501.121 | CG11: 5754.0897
A12: 011_Battus_ingenuus.png | B12: Papilionidae | C12: Battus | D12: 88144 | E12: 0.0097493519 | F12: 0.011290225 | G12: 0.013019406 | H12: 0.011521983 | I12: 0.010094754 | J12: 0.011826934 | K12: 0.014381788 | L12: 0.01162666 | M12: 0.0085276817 | N12: 0.0087476972 | O12: 0.010538197 | P12: 0.010344832 | Q12: 0.0084676393 | R12: 0.008401791 | S12: 0.011464513 | T12: 0.011252159 | U12: 0.0077903394 | V12: 0.0072365401 | W12: 0.0087849289 | X12: 0.0088571167 | Y12: 0.0073051722 | Z12: 0.0064385753 | AA12: 0.0095911967 | AB12: 0.0096904595 | AC12: 0.0064501364 | AD12: 0.0065755669 | AE12: 0.0070887088 | AF12: 0.0083353064 | AG12: 0.0059050075 | AH12: 0.0052795141 | AI12: 0.007518305 | AJ12: 0.0077811621 | AK12: 0.007443494 | AL12: 0.00099915504 | AM12: 0.0060902436 | AN12: 0.000524892 | AO12: 0.0048906864 | AP12: 0.00032699148 | AQ12: 7.4620183 | AR12: 1.8388573 | AS12: 11.224867 | AT12: 2.3229893 | AU12: 18.260482 | AV12: 1.2467483 | AW12: 0.89719391 | AX12: 0.025381036 | AY12: 0.845168 | AZ12: 0.032188331 | BA12: 0.7473169 | BB12: 0.017526885 | BC12: 1.7643846 | BD12: 0.24637373 | BE12: 2.1926085 | BF12: 0.2334455 | BG12: 2.8352988 | BH12: 0.1517315 | BI12: 0.08608251 | BJ12: 0.0057702338 | BK12: 0.077966626 | BL12: 0.0033836044 | BM12: 0.069894302 | BN12: 0.0023394392 | BO12: 0.48011478 | BP12: 0.03887085 | BQ12: 0.42156915 | BR12: 0.024621572 | BS12: 0.35871008 | BT12: 0.015216269 | BU12: 0.00012960318 | BV12: 466.45861 | BW12: 0.89927965 | BX12: 5.2642767 | BY12: 0.00013247266 | BZ12: 13.538078 | CA12: -0.20960881 | CB12: 0.97730584 | CC12: 0.10272734 | CD12: 254.4663 | CE12: 8.5190716 | CF12: 8797.2269 | CG12: 2315.9214
